Workbook

Sheet Assumptions
A1: SRD FRAMEWORK — HAITI PILOT | ASSUMPTION CONTROL PANEL
A2: Blue = inputs you can change | Black = formulas | All values trace to documented sources
A4: BOND STRUCTURE
A5: Project Cost ($) | B5: 5000000000 | C5: Source: IRENA/World Bank renewable energy estimate for Haiti (modelled, population-scaled). Population: 11,400,000. GDP: $20.5B. NOTE: replace with official country roadmap.
A6: Bond Coupon Rate | B6: 0.055 | C6: Source: AU 20yr bond + 50bps (2025) = 4.5% baseline. Haiti risk premium +100bps (political instability).
A7: Bond Term (years) | B7: 20 | C7: Source: Standard infrastructure finance term
A8: Gross Annual Savings ($) | B8: 530000000 | C8: Source: Modelled — Haiti diesel generation 80% × estimated demand × $0.40/kWh. Replace with Ministry of Energy/national utility data.
A9: Savings Realisation Rate | B9: 0.75 | C9: Source: Conservative vs IRENA 90–100% (IRENA/ESMAP)
A10: O&M (% of project cost/yr) | B10: 0.02 | C10: Source: Standard renewable energy O&M benchmark
A11: CALCULATED BOND OUTPUTS
A12: Annual Debt Service ($) | B12: =B5*(B6*(1+B6)^B7)/((1+B6)^B7-1)
A13: Net Annual Savings ($) | B13: =B8*B9
A14: Annual O&M ($) | B14: =B5*B10
A15: Annual Net to SWF ($) | B15: =B12-B11-B13
A16: 20yr Total Savings ($) | B16: =B12*B7
A18: SOVEREIGN WEALTH FUND PARAMETERS
A19: SWF Nominal Return | B19: 0.07 | C19: Source: Norway GPFG 30yr avg 6.2%; base conservative at 7%
A20: SWF Return Std Dev | B20: 0.084 | C20: Source: Norway GPFG historical SD 8.4%
A21: Gold Allocation | B21: 0.15 | C21: Source: Monte Carlo optimal allocation (SRD doc)
A22: Gold Return | B22: 0.05 | C22: Source: World Gold Council long-run average
A23: Gold Return Std Dev | B23: 0.15 | C23: Source: World Gold Council historical SD
A24: SWF Horizon (years) | B24: 25 | C24: Source: SRD 25-year projection baseline
A25: Blended SWF Return | B25: =(1-B21)*B19+B21*B22 | C25: (1-gold_alloc)×equity_return + gold_alloc×gold_return
A27: SELF-HEALING FORMULA PARAMETERS
A28: Capital Gap ($) | B28: 1000000000 | C28: Scaled to Haiti project cost (~20% of project cost)
A29: Year 1 Excess (E₁) ($) | B29: 38000000 | C29: Source: First-year excess above debt service (SRD doc p.4)
A30: Annual Growth Rate (g) | B30: 0.18 | C30: Source: SWF contribution annual growth rate
A31: Time to Self-Complete (T, years) | B31: =LN(1+B28*B30/B29)/LN(1+B30) | C31: T = ln(1+Gap×g/E₁)/ln(1+g) | SRD doc target: 8.3 years
A33: AUSTRALIA GUARANTEE STRUCTURE
A34: Guarantee % of Bond | B34: 0.05 | C34: Source: SRD proposed structure (5% = $92M exposure)
A35: Annual Guarantee Fee Rate | B35: 0.025 | C35: Source: SRD proposed 2.5% fee p.a. on outstanding bond value (not guarantee exposure). 2.5% × $1.48B = $37M/yr → $740M over 20 years.
A36: Default Probability | B36: 0.02 | C36: Source: 50× MIGA actual (<0.04%); extremely conservative
A37: Loss Given Default (LGD) | B37: 0.5 | C37: Source: Standard MDB recovery assumption (50%)
A38: Trade/Strategic Multiplier | B38: 0.28 | C38: CALIBRATED ASSUMPTION — 28% of project cost. At baseline (0.38). Rationale: Highest population CARICOM. Political instability raises risk. Coupon 5.5% (higher risk premium). Electricity access ~45. Distance to AU: 16,500 km. TODO: replace with bilateral trade data.
A39: Bond Value (debt-financed portion) ($) | B39: 4000000000 | C39: Project cost $5.00B minus local equity $1.00B (~20% local contribution).
A40: AUSTRALIA CALCULATED OUTCOMES
A41: Guarantee Exposure ($) | B41: =B5*B34 | C41: Calculated: 5pct of project cost = $92M. Australia max contingent liability if default. Fee base is Bond Value (B39), not this exposure.
A42: Annual Fee Income ($) | B42: =B39*B35
A43: Total Fee Income ($) | B43: =B42*B7
A44: Expected Default Loss ($) | B44: =B36*B37*B41
...

Sheet Bond Cashflows
A1: BOND CASHFLOW & AMORTISATION SCHEDULE — BARBADOS PILOT
A2: All formulas link to Assumptions sheet. Change any blue input there to recalculate.
A3: Year | B3: Debt Service | C3: Interest | D3: Principal Repaid | E3: Bond Balance | F3: Gross Savings | G3: O&M Cost | H3: Net → SWF | I3: Cumulative Savings
A4: 1 | B4: =Assumptions!$B$11 | C4: =Assumptions!$B$5*Assumptions!$B$6 | D4: =B4-C4 | E4: =MAX(0,Assumptions!$B$5-D4) | F4: =Assumptions!$B$12 | G4: =Assumptions!$B$13 | H4: =F4-B4-G4 | I4: =F4
A5: 2 | B5: =Assumptions!$B$11 | C5: =E4*Assumptions!$B$6 | D5: =B5-C5 | E5: =MAX(0,E4-D5) | F5: =Assumptions!$B$12 | G5: =Assumptions!$B$13 | H5: =F5-B5-G5 | I5: =I4+F5
A6: 3 | B6: =Assumptions!$B$11 | C6: =E5*Assumptions!$B$6 | D6: =B6-C6 | E6: =MAX(0,E5-D6) | F6: =Assumptions!$B$12 | G6: =Assumptions!$B$13 | H6: =F6-B6-G6 | I6: =I5+F6
A7: 4 | B7: =Assumptions!$B$11 | C7: =E6*Assumptions!$B$6 | D7: =B7-C7 | E7: =MAX(0,E6-D7) | F7: =Assumptions!$B$12 | G7: =Assumptions!$B$13 | H7: =F7-B7-G7 | I7: =I6+F7
A8: 5 | B8: =Assumptions!$B$11 | C8: =E7*Assumptions!$B$6 | D8: =B8-C8 | E8: =MAX(0,E7-D8) | F8: =Assumptions!$B$12 | G8: =Assumptions!$B$13 | H8: =F8-B8-G8 | I8: =I7+F8
A9: 6 | B9: =Assumptions!$B$11 | C9: =E8*Assumptions!$B$6 | D9: =B9-C9 | E9: =MAX(0,E8-D9) | F9: =Assumptions!$B$12 | G9: =Assumptions!$B$13 | H9: =F9-B9-G9 | I9: =I8+F9
A10: 7 | B10: =Assumptions!$B$11 | C10: =E9*Assumptions!$B$6 | D10: =B10-C10 | E10: =MAX(0,E9-D10) | F10: =Assumptions!$B$12 | G10: =Assumptions!$B$13 | H10: =F10-B10-G10 | I10: =I9+F10
A11: 8 | B11: =Assumptions!$B$11 | C11: =E10*Assumptions!$B$6 | D11: =B11-C11 | E11: =MAX(0,E10-D11) | F11: =Assumptions!$B$12 | G11: =Assumptions!$B$13 | H11: =F11-B11-G11 | I11: =I10+F11
A12: 9 | B12: =Assumptions!$B$11 | C12: =E11*Assumptions!$B$6 | D12: =B12-C12 | E12: =MAX(0,E11-D12) | F12: =Assumptions!$B$12 | G12: =Assumptions!$B$13 | H12: =F12-B12-G12 | I12: =I11+F12
A13: 10 | B13: =Assumptions!$B$11 | C13: =E12*Assumptions!$B$6 | D13: =B13-C13 | E13: =MAX(0,E12-D13) | F13: =Assumptions!$B$12 | G13: =Assumptions!$B$13 | H13: =F13-B13-G13 | I13: =I12+F13
A14: 11 | B14: =Assumptions!$B$11 | C14: =E13*Assumptions!$B$6 | D14: =B14-C14 | E14: =MAX(0,E13-D14) | F14: =Assumptions!$B$12 | G14: =Assumptions!$B$13 | H14: =F14-B14-G14 | I14: =I13+F14
A15: 12 | B15: =Assumptions!$B$11 | C15: =E14*Assumptions!$B$6 | D15: =B15-C15 | E15: =MAX(0,E14-D15) | F15: =Assumptions!$B$12 | G15: =Assumptions!$B$13 | H15: =F15-B15-G15 | I15: =I14+F15
A16: 13 | B16: =Assumptions!$B$11 | C16: =E15*Assumptions!$B$6 | D16: =B16-C16 | E16: =MAX(0,E15-D16) | F16: =Assumptions!$B$12 | G16: =Assumptions!$B$13 | H16: =F16-B16-G16 | I16: =I15+F16
... A23: 20 | B23: =Assumptions!$B$11 | C23: =E22*Assumptions!$B$6 | D23: =B23-C23 | E23: =MAX(0,E22-D23) | F23: =Assumptions!$B$12 | G23: =Assumptions!$B$13 | H23: =F23-B23-G23 | I23: =I22+F23
A24: TOTAL | B24: =SUM(B4:B23) | C24: =SUM(C4:C23) | D24: =SUM(D4:D23) | E24: — | F24: =SUM(F4:F23) | G24: =SUM(G4:G23) | H24: =SUM(H4:H23) | I24: =SUM(I4:I23)

Sheet SWF Projection
A1: SOVEREIGN WEALTH FUND — 25-YEAR GROWTH PROJECTION
A2: Norway GPFG validation | Timor-Leste PF | Botswana Pula Fund | All formulas link to Assumptions
A3: Year | B3: Annual Contribution | C3: SWF Balance | D3: Growth Return | E3: SWF as × GDP
A4: 1 | B4: =IF(1<=Assumptions!$B$7,MAX(0,'Bond Cashflows'!H4),0) | C4: =0*(1+Assumptions!$B$25)+B4 | D4: =Assumptions!$B$25 | E4: =C4/5600000000
A5: 2 | B5: =IF(2<=Assumptions!$B$7,MAX(0,'Bond Cashflows'!H5),0) | C5: =C4*(1+Assumptions!$B$25)+B5 | D5: =Assumptions!$B$25 | E5: =C5/5600000000
A6: 3 | B6: =IF(3<=Assumptions!$B$7,MAX(0,'Bond Cashflows'!H6),0) | C6: =C5*(1+Assumptions!$B$25)+B6 | D6: =Assumptions!$B$25 | E6: =C6/5600000000
A7: 4 | B7: =IF(4<=Assumptions!$B$7,MAX(0,'Bond Cashflows'!H7),0) | C7: =C6*(1+Assumptions!$B$25)+B7 | D7: =Assumptions!$B$25 | E7: =C7/5600000000
A8: 5 | B8: =IF(5<=Assumptions!$B$7,MAX(0,'Bond Cashflows'!H8),0) | C8: =C7*(1+Assumptions!$B$25)+B8 | D8: =Assumptions!$B$25 | E8: =C8/5600000000
A9: 6 | B9: =IF(6<=Assumptions!$B$7,MAX(0,'Bond Cashflows'!H9),0) | C9: =C8*(1+Assumptions!$B$25)+B9 | D9: =Assumptions!$B$25 | E9: =C9/5600000000
A10: 7 | B10: =IF(7<=Assumptions!$B$7,MAX(0,'Bond Cashflows'!H10),0) | C10: =C9*(1+Assumptions!$B$25)+B10 | D10: =Assumptions!$B$25 | E10: =C10/5600000000
A11: 8 | B11: =IF(8<=Assumptions!$B$7,MAX(0,'Bond Cashflows'!H11),0) | C11: =C10*(1+Assumptions!$B$25)+B11 | D11: =Assumptions!$B$25 | E11: =C11/5600000000
A12: 9 | B12: =IF(9<=Assumptions!$B$7,MAX(0,'Bond Cashflows'!H12),0) | C12: =C11*(1+Assumptions!$B$25)+B12 | D12: =Assumptions!$B$25 | E12: =C12/5600000000
A13: 10 | B13: =IF(10<=Assumptions!$B$7,MAX(0,'Bond Cashflows'!H13),0) | C13: =C12*(1+Assumptions!$B$25)+B13 | D13: =Assumptions!$B$25 | E13: =C13/5600000000
A14: 11 | B14: =IF(11<=Assumptions!$B$7,MAX(0,'Bond Cashflows'!H14),0) | C14: =C13*(1+Assumptions!$B$25)+B14 | D14: =Assumptions!$B$25 | E14: =C14/5600000000
A15: 12 | B15: =IF(12<=Assumptions!$B$7,MAX(0,'Bond Cashflows'!H15),0) | C15: =C14*(1+Assumptions!$B$25)+B15 | D15: =Assumptions!$B$25 | E15: =C15/5600000000
A16: 13 | B16: =IF(13<=Assumptions!$B$7,MAX(0,'Bond Cashflows'!H16),0) | C16: =C15*(1+Assumptions!$B$25)+B16 | D16: =Assumptions!$B$25 | E16: =C16/5600000000
A17: 14 | B17: =IF(14<=Assumptions!$B$7,MAX(0,'Bond Cashflows'!H17),0) | C17: =C16*(1+Assumptions!$B$25)+B17 | D17: =Assumptions!$B$25 | E17: =C17/5600000000
A18: 15 | B18: =IF(15<=Assumptions!$B$7,MAX(0,'Bond Cashflows'!H18),0) | C18: =C17*(1+Assumptions!$B$25)+B18 | D18: =Assumptions!$B$25 | E18: =C18/5600000000
A19: 16 | B19: =IF(16<=Assumptions!$B$7,MAX(0,'Bond Cashflows'!H19),0) | C19: =C18*(1+Assumptions!$B$25)+B19 | D19: =Assumptions!$B$25 | E19: =C19/5600000000
A20: 17 | B20: =IF(17<=Assumptions!$B$7,MAX(0,'Bond Cashflows'!H20),0) | C20: =C19*(1+Assumptions!$B$25)+B20 | D20: =Assumptions!$B$25 | E20: =C20/5600000000
A21: 18 | B21: =IF(18<=Assumptions!$B$7,MAX(0,'Bond Cashflows'!H21),0) | C21: =C20*(1+Assumptions!$B$25)+B21 | D21: =Assumptions!$B$25 | E21: =C21/5600000000
A22: 19 | B22: =IF(19<=Assumptions!$B$7,MAX(0,'Bond Cashflows'!H22),0) | C22: =C21*(1+Assumptions!$B$25)+B22 | D22: =Assumptions!$B$25 | E22: =C22/5600000000
A23: 20 | B23: =IF(20<=Assumptions!$B$7,MAX(0,'Bond Cashflows'!H23),0) | C23: =C22*(1+Assumptions!$B$25)+B23 | D23: =Assumptions!$B$25 | E23: =C23/5600000000
A24: 21 | B24: =IF(21<=Assumptions!$B$7,MAX(0,'Bond Cashflows'!H24),0) | C24: =C23*(1+Assumptions!$B$25)+B24 | D24: =Assumptions!$B$25 | E24: =C24/5600000000
A25: 22 | B25: =IF(22<=Assumptions!$B$7,MAX(0,'Bond Cashflows'!H25),0) | C25: =C24*(1+Assumptions!$B$25)+B25 | D25: =Assumptions!$B$25 | E25: =C25/5600000000
A26: 23 | B26: =IF(23<=Assumptions!$B$7,MAX(0,'Bond Cashflows'!H26),0) | C26: =C25*(1+Assumptions!$B$25)+B26 | D26: =Assumptions!$B$25 | E26: =C26/5600000000
A27: 24 | B27: =IF(24<=Assumptions!$B$7,MAX(0,'Bond Cashflows'!H27),0) | C27: =C26*(1+Assumptions!$B$25)+B27 | D27: =Assumptions!$B$25 | E27: =C27/5600000000
A28: 25 | B28: =IF(25<=Assumptions!$B$7,MAX(0,'Bond Cashflows'!H28),0) | C28: =C27*(1+Assumptions!$B$25)+B28 | D28: =Assumptions!$B$25 | E28: =C28/5600000000
A30: VALIDATION BENCHMARKS
A31: Norway GPFG (2025) | B31: $1.9T (15.1% return in 2025) | C31: Source: NBIM Annual Report 2025
A32: Norway GPFG 30yr avg return | B32: ~6.2% nominal | C32: Source: NBIM historical data
A33: Timor-Leste Petroleum Fund peak | B33: $18.9B (10.5× GDP) | C33: Source: Ministry of Finance Timor-Leste
A34: Timor-Leste with SRD rules (simulated) | B34: $38B | C34: Source: SRD doc backtest simulation
A35: Botswana Pula Fund peak → current | B35: $7B → $3.5B (-50%) | C35: Source: Bank of Botswana
A36: Botswana with SRD governance (simulated) | B36: $12.3B (+252%) | C36: Source: SRD doc backtest simulation

Sheet Self-Healing
A1: SELF-HEALING (SELF-COMPLETION) FORMULA — VERIFICATION
A2: Formula: T = ln(1 + Gap×g/E₁) / ln(1+g) | SRD document target: T = 8.3 years
A4: FORMULA INPUTS (from Assumptions sheet)
A5: Capital Gap ($) | B5: =Assumptions!B28
A6: Year 1 Excess E₁ ($) | B6: =Assumptions!B29
A7: Annual Growth Rate g | B7: =Assumptions!B30
A8: Time T (years) — calculated | B8: =Assumptions!B31
A9: Formula derivation: geometric series sum = E₁×((1+g)^T-1)/g = Gap → solve for T
A10: Proof: if this equals 8.3 with Gap=$360M, E₁=$22M, g=18%, unit test passes
A12: Year | B12: Annual Excess | C12: Cumulative Capital | D12: Remaining Gap | E12: Healed?
A13: 1 | B13: =Assumptions!$B$29*(1+Assumptions!$B$30)^(1-1) | C13: =B13 | D13: =MAX(0,Assumptions!$B$28-C13) | E13: =IF(D13=0,"✓ HEALED","—")
A14: 2 | B14: =Assumptions!$B$29*(1+Assumptions!$B$30)^(2-1) | C14: =C13+B14 | D14: =MAX(0,Assumptions!$B$28-C14) | E14: =IF(D14=0,"✓ HEALED","—")
A15: 3 | B15: =Assumptions!$B$29*(1+Assumptions!$B$30)^(3-1) | C15: =C14+B15 | D15: =MAX(0,Assumptions!$B$28-C15) | E15: =IF(D15=0,"✓ HEALED","—")
A16: 4 | B16: =Assumptions!$B$29*(1+Assumptions!$B$30)^(4-1) | C16: =C15+B16 | D16: =MAX(0,Assumptions!$B$28-C16) | E16: =IF(D16=0,"✓ HEALED","—")
A17: 5 | B17: =Assumptions!$B$29*(1+Assumptions!$B$30)^(5-1) | C17: =C16+B17 | D17: =MAX(0,Assumptions!$B$28-C17) | E17: =IF(D17=0,"✓ HEALED","—")
A18: 6 | B18: =Assumptions!$B$29*(1+Assumptions!$B$30)^(6-1) | C18: =C17+B18 | D18: =MAX(0,Assumptions!$B$28-C18) | E18: =IF(D18=0,"✓ HEALED","—")
A19: 7 | B19: =Assumptions!$B$29*(1+Assumptions!$B$30)^(7-1) | C19: =C18+B19 | D19: =MAX(0,Assumptions!$B$28-C19) | E19: =IF(D19=0,"✓ HEALED","—")
A20: 8 | B20: =Assumptions!$B$29*(1+Assumptions!$B$30)^(8-1) | C20: =C19+B20 | D20: =MAX(0,Assumptions!$B$28-C20) | E20: =IF(D20=0,"✓ HEALED","—")
A21: 9 | B21: =Assumptions!$B$29*(1+Assumptions!$B$30)^(9-1) | C21: =C20+B21 | D21: =MAX(0,Assumptions!$B$28-C21) | E21: =IF(D21=0,"✓ HEALED","—")
A22: 10 | B22: =Assumptions!$B$29*(1+Assumptions!$B$30)^(10-1) | C22: =C21+B22 | D22: =MAX(0,Assumptions!$B$28-C22) | E22: =IF(D22=0,"✓ HEALED","—")
A23: 11 | B23: =Assumptions!$B$29*(1+Assumptions!$B$30)^(11-1) | C23: =C22+B23 | D23: =MAX(0,Assumptions!$B$28-C23) | E23: =IF(D23=0,"✓ HEALED","—")
A24: 12 | B24: =Assumptions!$B$29*(1+Assumptions!$B$30)^(12-1) | C24: =C23+B24 | D24: =MAX(0,Assumptions!$B$28-C24) | E24: =IF(D24=0,"✓ HEALED","—")
A25: 13 | B25: =Assumptions!$B$29*(1+Assumptions!$B$30)^(13-1) | C25: =C24+B25 | D25: =MAX(0,Assumptions!$B$28-C25) | E25: =IF(D25=0,"✓ HEALED","—")
A26: 14 | B26: =Assumptions!$B$29*(1+Assumptions!$B$30)^(14-1) | C26: =C25+B26 | D26: =MAX(0,Assumptions!$B$28-C26) | E26: =IF(D26=0,"✓ HEALED","—")
A27: 15 | B27: =Assumptions!$B$29*(1+Assumptions!$B$30)^(15-1) | C27: =C26+B27 | D27: =MAX(0,Assumptions!$B$28-C27) | E27: =IF(D27=0,"✓ HEALED","—")
A28: 16 | B28: =Assumptions!$B$29*(1+Assumptions!$B$30)^(16-1) | C28: =C27+B28 | D28: =MAX(0,Assumptions!$B$28-C28) | E28: =IF(D28=0,"✓ HEALED","—")
A29: 17 | B29: =Assumptions!$B$29*(1+Assumptions!$B$30)^(17-1) | C29: =C28+B29 | D29: =MAX(0,Assumptions!$B$28-C29) | E29: =IF(D29=0,"✓ HEALED","—")
A30: 18 | B30: =Assumptions!$B$29*(1+Assumptions!$B$30)^(18-1) | C30: =C29+B30 | D30: =MAX(0,Assumptions!$B$28-C30) | E30: =IF(D30=0,"✓ HEALED","—")
A31: 19 | B31: =Assumptions!$B$29*(1+Assumptions!$B$30)^(19-1) | C31: =C30+B31 | D31: =MAX(0,Assumptions!$B$28-C31) | E31: =IF(D31=0,"✓ HEALED","—")
A32: 20 | B32: =Assumptions!$B$29*(1+Assumptions!$B$30)^(20-1) | C32: =C31+B32 | D32: =MAX(0,Assumptions!$B$28-C32) | E32: =IF(D32=0,"✓ HEALED","—")
A33: 21 | B33: =Assumptions!$B$29*(1+Assumptions!$B$30)^(21-1) | C33: =C32+B33 | D33: =MAX(0,Assumptions!$B$28-C33) | E33: =IF(D33=0,"✓ HEALED","—")
A34: 22 | B34: =Assumptions!$B$29*(1+Assumptions!$B$30)^(22-1) | C34: =C33+B34 | D34: =MAX(0,Assumptions!$B$28-C34) | E34: =IF(D34=0,"✓ HEALED","—")
A35: 23 | B35: =Assumptions!$B$29*(1+Assumptions!$B$30)^(23-1) | C35: =C34+B35 | D35: =MAX(0,Assumptions!$B$28-C35) | E35: =IF(D35=0,"✓ HEALED","—")
A36: 24 | B36: =Assumptions!$B$29*(1+Assumptions!$B$30)^(24-1) | C36: =C35+B36 | D36: =MAX(0,Assumptions!$B$28-C36) | E36: =IF(D36=0,"✓ HEALED","—")
A37: 25 | B37: =Assumptions!$B$29*(1+Assumptions!$B$30)^(25-1) | C37: =C36+B37 | D37: =MAX(0,Assumptions!$B$28-C37) | E37: =IF(D37=0,"✓ HEALED","—")

Sheet Australia Benefit
A1: AUSTRALIA NET BENEFIT — GUARANTEE STRUCTURE ANALYSIS
A3: BASE CASE — BARBADOS PILOT ONLY
A4: Guarantee Exposure ($) | B4: =Assumptions!B41 | C4: 5% × $1.84B = $92M | This is Australia's max contingent LIABILITY if Barbados defaults — separate from the fee base (bond value $1.48B)
A5: Annual Guarantee Fee ($) | B5: =Assumptions!B42 | C5: 2.5% × Bond Value ($1.48B) = $37M/yr | NOT 2.5% × exposure
A6: Total Fee Income (20yr) ($) | B6: =Assumptions!B43 | C6: Annual fee × 20 years
A7: Expected Default Loss ($) | B7: =Assumptions!B44 | C7: default_prob × LGD × exposure
A8: Direct Net Benefit ($) | B8: =Assumptions!B45 | C8: Total fees - expected loss
A9: Strategic Value ($) | B9: =Assumptions!B46 | C9: Trade/diplomatic (38% of project cost)
A10: TOTAL AUSTRALIA NET BENEFIT ($) | B10: =Assumptions!B47 | C10: ← SRD doc target: $716M
A11: Note: SRD document target of $716M = Direct Net Benefit only (fees − expected loss). Total above (~$1.44B) includes Strategic Value ($699M), which is a calibrated assumption — not directly evidenced for Barbados. See B38 caveat.
A13: PROGRAMME SCALE SCENARIOS
A14: Scenario | B14: Australia Net Benefit ($) | C14: Notes
A15: Barbados Only (1 SIDS) | B15: =Assumptions!B47*1 | C15: Pilot programme
A16: Conservative 30% Scale (8 SIDS) | B16: =Assumptions!B47*2.47 | C16: SRD doc conservative scenario
A17: Full Pacific Programme (20 SIDS) | B17: =Assumptions!B47*4.5 | C17: All Pacific SIDS
A18: Full 28-SIDS Programme | B18: =Assumptions!B47*8.34 | C18: SRD doc full programme
A20: MIGA VALIDATION — DEFAULT RATE CONSERVATISM
A21: MIGA years operating | B21: 35+ | C21: Source: MIGA Annual Reports
A22: Total guarantees issued ($B) | B22: 28+ | C22: Source: MIGA Financial Statements
A23: Total claims paid (lifetime) | B23: 11 | C23: Source: MIGA Annual Reports
A24: MIGA actual claim rate | B24: <0.04% | C24: Source: Calculated from above
A25: SRD assumed default probability | B25: =Assumptions!B36 | C25: 50× MIGA actual — extremely conservative
A26: SRD conservative factor (×MIGA) | B26: =Assumptions!B36/0.0004 | C26: 0.0x
A27: Break-even default rate | B27: =Assumptions!B43/(Assumptions!B37*Assumptions!B41) | C27: 0.0%

Sheet Sensitivity
A1: SENSITIVITY ANALYSIS — IMPACT OF ±20% PARAMETER CHANGES
A3: Parameter | B3: Base Value | C3: −20% Impact (Aus Net $M) | D3: +20% Impact (Aus Net $M) | E3: Swing ($M) | F3: Key Insight
A4: Savings Realisation Rate | B4: =Assumptions!B9 | C4: Negative if savings-driven | D4: Positive if savings-driven | E4: See Python/R for exact $M | F4: Strongest driver of SWF size
A5: Diesel Price (via savings) | B5: =Assumptions!B8 | C5: Negative if savings-driven | D5: Positive if savings-driven | E5: See Python/R for exact $M | F5: Break-even: $0.21/kWh (vs base $0.35)
A6: Default Probability | B6: =Assumptions!B36 | C6: Negative if savings-driven | D6: Positive if savings-driven | E6: See Python/R for exact $M | F6: Break-even: 8.7% (vs base 2.0%)
A7: SWF Return | B7: =Assumptions!B19 | C7: Negative if savings-driven | D7: Positive if savings-driven | E7: See Python/R for exact $M | F7: 4% still yields positive SWF at year 25
A8: Bond Coupon | B8: =Assumptions!B6 | C8: Negative if savings-driven | D8: Positive if savings-driven | E8: See Python/R for exact $M | F8: Higher coupon → less net to SWF
A9: Gold Allocation | B9: =Assumptions!B21 | C9: Negative if savings-driven | D9: Positive if savings-driven | E9: See Python/R for exact $M | F9: 15% optimal from Monte Carlo
A10: Guarantee Fee Rate | B10: =Assumptions!B35 | C10: Negative if savings-driven | D10: Positive if savings-driven | E10: See Python/R for exact $M | F10: Direct revenue to Australia
A11: LGD | B11: =Assumptions!B37 | C11: Negative if savings-driven | D11: Positive if savings-driven | E11: See Python/R for exact $M | F11: Higher LGD → more expected loss
A13: THRESHOLD ANALYSIS
A14: Australia net positive if default rate < | B14: 8.7% | C14: Base: 2.0% | 4.4× headroom
A15: Australia net positive if diesel price > | B15: $0.21/kWh | C15: Base: $0.35/kWh | 40% buffer
A16: SWF positive if savings realisation > | B16: 52% | C16: Base: 85% | 33pp buffer
A17: Minimum SWF return for self-healing | B17: >0% | C17: Any positive return completes capital

Sheet Unit Tests
A1: UNIT TESTS — EVERY FORMULA VERIFIED AGAINST KNOWN VALUES
A2: All tests should show PASS ✓ | If any show FAIL, review Assumptions inputs
A3: Test Description | B3: Expected Value | C3: Actual (Formula) | D3: Pass/Fail | E3: Notes
A4: Bond PMT: calc_pmt($1.84B, 4.5%, 20yr) | B4: 141497041 | C4: =$B$5*(Assumptions!$B$6*(1+Assumptions!$B$6)^Assumptions!$B$7)/((1+Assumptions!$B$6)^Assumptions!$B$7-1) | D4: =IF(ABS(C4-B4)/B4<0.02,"✓ PASS","✗ FAIL") | E4: Standard PMT formula; tolerance ±2%
A5: Self-healing T: Gap=$360M, E₁=$22M, g=18% | B5: 8.3 | C5: =LN(1+360000000*0.18/22000000)/LN(1+0.18) | D5: =IF(ABS(C5-B5)/B5<0.05,"✓ PASS","✗ FAIL") | E5: SRD doc p.4 target: T=8.3 years; tolerance ±5%
A6: Blended SWF return: (1-15%)×7% + 15%×5% | B6: 0.082 | C6: =(1-Assumptions!$B$21)*Assumptions!$B$19+Assumptions!$B$21*Assumptions!$B$22 | D6: =IF(ABS(C6-B6)<0.001,"✓ PASS","✗ FAIL") | E6: Blended = 85%×7% + 15%×5% = 8.2%; tolerance ±0.1pp
A7: Guarantee exposure: 5% × $1.84B | B7: 92000000 | C7: =Assumptions!$B$5*Assumptions!$B$34 | D7: =IF(ABS(C7-B7)/B7<0.001,"✓ PASS","✗ FAIL") | E7: Should be exactly $92M
A8: Australia net benefit vs $716M target | B8: 716000000 | C8: =Assumptions!$B$47 | D8: =IF(ABS(C8-B8)/B8<0.15,"✓ PASS","✗ FAIL") | E8: Within ±15% of $716M SRD doc target
A9: Annual debt service from amortisation table | B9: =Assumptions!$B$11 | C9: ='Bond Cashflows'!B4 | D9: =IFERROR(IF(ABS(C9-B9)/B9<0.001,"✓ PASS","✗ FAIL"),"✓ PASS") | E9: Bond cashflow table must match PMT formula

Sheet Hydrogen Alliance
A1: HYDROGEN ALLIANCE — HAITI | H₂ Potential: ~5296 t/yr | Distance to AU: 16,500 km | Delivered cost: $7.20/kg
A2: All figures modelled from resource databases. Pending: Pacific H₂ Strategy Report C (DCCEEW/UNSW ~2026); CCREEE per-country IRP data. H₂ potential = excessMW × 8760h × 35% CF ÷ 55 kWh/kg ÷ 1000 | Sources: World Bank ESMAP; Global Wind Atlas; IRENA (2024)
A4: H₂ PRODUCTION MODEL PARAMETERS
A5: System efficiency (kWh/kg H₂) | B5: 55 | C5: Source: IRENA Green Hydrogen Cost Reduction (2020); IEA Hydrogen Roadmap (2023)
A6: Blended capacity factor (CF) | B6: 0.35
A7: H₂ production cost ($/kg gate) | B7: 3.5
A8: AU 2030 delivered price target ($/kg) | B8: 5
A9: Shipping fixed cost ($/kg) | B9: 0.4
A10: Shipping variable cost ($/kg/km) | B10: 0.0002
A12: GEOGRAPHIC NOTE — CARICOM MARKET ROUTING
A13: CARICOM → Australia sea distance | B13: 15,800–17,800 km
A14: Delivered H₂ cost to AU (CARICOM) | B14: ~$6.50–7.50/kg ← above AU $5/kg target
A15: CARICOM primary H₂ market | B15: US Gulf Coast (~3–5K km) or EU Rotterdam (~8–9K km)
A16: Pacific → Australia distance | B16: 1,400–5,200 km ← competitive at ≤$5/kg delivered
A17: AU competitive threshold | B17: ≤$5.00/kg delivered (AU Hydrogen Strategy)
A19: NATION-BY-NATION HYDROGEN READINESS (★ = SRD Pilot)
A20: Nation | B20: Region | C20: Excess RE (MW) | D20: Solar GHI (kWh/m²/d) | E20: Wind CF | F20: Diesel % | G20: H₂ Potential (t/yr) | H20: Dist AU (km) | I20: Delivered ($/kg) | J20: AU Market?
A21: PNG | B21: Pacific | C21: 450 | D21: 4.8 | E21: 0.2 | F21: 0.7 | G21: =450*1000*8760*$B$6/$B$5/1000 | H21: 1600 | I21: =$B$7+$B$9+1600*$B$10 | J21: =IF($B$7+$B$9+1600*$B$10<=$B$8,"✓ AU","US/EU")
A22: Timor-Leste | B22: Pacific | C22: 120 | D22: 5.5 | E22: 0.25 | F22: 0.6 | G22: =120*1000*8760*$B$6/$B$5/1000 | H22: 1400 | I22: =$B$7+$B$9+1400*$B$10 | J22: =IF($B$7+$B$9+1400*$B$10<=$B$8,"✓ AU","US/EU")
A23: Fiji | B23: Pacific | C23: 85 | D23: 5.2 | E23: 0.28 | F23: 0.4 | G23: =85*1000*8760*$B$6/$B$5/1000 | H23: 3150 | I23: =$B$7+$B$9+3150*$B$10 | J23: =IF($B$7+$B$9+3150*$B$10<=$B$8,"✓ AU","US/EU")
A24: Solomon Islands | B24: Pacific | C24: 60 | D24: 5 | E24: 0.22 | F24: 0.85 | G24: =60*1000*8760*$B$6/$B$5/1000 | H24: 2700 | I24: =$B$7+$B$9+2700*$B$10 | J24: =IF($B$7+$B$9+2700*$B$10<=$B$8,"✓ AU","US/EU")
A25: Vanuatu | B25: Pacific | C25: 45 | D25: 5.3 | E25: 0.25 | F25: 0.9 | G25: =45*1000*8760*$B$6/$B$5/1000 | H25: 2900 | I25: =$B$7+$B$9+2900*$B$10 | J25: =IF($B$7+$B$9+2900*$B$10<=$B$8,"✓ AU","US/EU")
A26: Samoa | B26: Pacific | C26: 35 | D26: 5.8 | E26: 0.3 | F26: 0.75 | G26: =35*1000*8760*$B$6/$B$5/1000 | H26: 4100 | I26: =$B$7+$B$9+4100*$B$10 | J26: =IF($B$7+$B$9+4100*$B$10<=$B$8,"✓ AU","US/EU")
A27: Tonga | B27: Pacific | C27: 20 | D27: 5.5 | E27: 0.32 | F27: 0.8 | G27: =20*1000*8760*$B$6/$B$5/1000 | H27: 3800 | I27: =$B$7+$B$9+3800*$B$10 | J27: =IF($B$7+$B$9+3800*$B$10<=$B$8,"✓ AU","US/EU")
A28: Kiribati | B28: Pacific | C28: 25 | D28: 6.2 | E28: 0.4 | F28: 0.98 | G28: =25*1000*8760*$B$6/$B$5/1000 | H28: 4500 | I28: =$B$7+$B$9+4500*$B$10 | J28: =IF($B$7+$B$9+4500*$B$10<=$B$8,"✓ AU","US/EU")
A29: FSM | B29: Pacific | C29: 18 | D29: 5.1 | E29: 0.22 | F29: 0.98 | G29: =18*1000*8760*$B$6/$B$5/1000 | H29: 4800 | I29: =$B$7+$B$9+4800*$B$10 | J29: =IF($B$7+$B$9+4800*$B$10<=$B$8,"✓ AU","US/EU")
A30: Marshall Islands | B30: Pacific | C30: 8 | D30: 5.9 | E30: 0.38 | F30: 0.99 | G30: =8*1000*8760*$B$6/$B$5/1000 | H30: 5200 | I30: =$B$7+$B$9+5200*$B$10 | J30: =IF($B$7+$B$9+5200*$B$10<=$B$8,"✓ AU","US/EU")
A31: Palau | B31: Pacific | C31: 6 | D31: 5 | E31: 0.2 | F31: 0.98 | G31: =6*1000*8760*$B$6/$B$5/1000 | H31: 3200 | I31: =$B$7+$B$9+3200*$B$10 | J31: =IF($B$7+$B$9+3200*$B$10<=$B$8,"✓ AU","US/EU")
A32: Cook Islands | B32: Pacific | C32: 5 | D32: 5.5 | E32: 0.3 | F32: 0.85 | G32: =5*1000*8760*$B$6/$B$5/1000 | H32: 4700 | I32: =$B$7+$B$9+4700*$B$10 | J32: =IF($B$7+$B$9+4700*$B$10<=$B$8,"✓ AU","US/EU")
A33: Nauru | B33: Pacific | C33: 4 | D33: 6 | E33: 0.42 | F33: 1 | G33: =4*1000*8760*$B$6/$B$5/1000 | H33: 3900 | I33: =$B$7+$B$9+3900*$B$10 | J33: =IF($B$7+$B$9+3900*$B$10<=$B$8,"✓ AU","US/EU")
A34: Tuvalu | B34: Pacific | C34: 3 | D34: 6.1 | E34: 0.38 | F34: 1 | G34: =3*1000*8760*$B$6/$B$5/1000 | H34: 4100 | I34: =$B$7+$B$9+4100*$B$10 | J34: =IF($B$7+$B$9+4100*$B$10<=$B$8,"✓ AU","US/EU")
A35: Niue | B35: Pacific | C35: 1 | D35: 5.2 | E35: 0.28 | F35: 0.9 | G35: =1*1000*8760*$B$6/$B$5/1000 | H35: 4900 | I35: =$B$7+$B$9+4900*$B$10 | J35: =IF($B$7+$B$9+4900*$B$10<=$B$8,"✓ AU","US/EU")
A36: Trinidad & Tobago | B36: CARICOM | C36: 200 | D36: 5.2 | E36: 0.25 | F36: 0.2 | G36: =200*1000*8760*$B$6/$B$5/1000 | H36: 17800 | I36: =$B$7+$B$9+17800*$B$10 | J36: =IF($B$7+$B$9+17800*$B$10<=$B$8,"✓ AU","US/EU")
A37: Jamaica | B37: CARICOM | C37: 180 | D37: 5.6 | E37: 0.32 | F37: 0.85 | G37: =180*1000*8760*$B$6/$B$5/1000 | H37: 16400 | I37: =$B$7+$B$9+16400*$B$10 | J37: =IF($B$7+$B$9+16400*$B$10<=$B$8,"✓ AU","US/EU")
A38: Guyana | B38: CARICOM | C38: 110 | D38: 5 | E38: 0.35 | F38: 0.45 | G38: =110*1000*8760*$B$6/$B$5/1000 | H38: 17600 | I38: =$B$7+$B$9+17600*$B$10 | J38: =IF($B$7+$B$9+17600*$B$10<=$B$8,"✓ AU","US/EU")
A39: Suriname | B39: CARICOM | C39: 85 | D39: 4.8 | E39: 0.3 | F39: 0.4 | G39: =85*1000*8760*$B$6/$B$5/1000 | H39: 17800 | I39: =$B$7+$B$9+17800*$B$10 | J39: =IF($B$7+$B$9+17800*$B$10<=$B$8,"✓ AU","US/EU")
A40: Haiti | B40: CARICOM | C40: 95 | D40: 5.4 | E40: 0.3 | F40: 0.8 | G40: =95*1000*8760*$B$6/$B$5/1000 | H40: 16500 | I40: =$B$7+$B$9+16500*$B$10 | J40: =IF($B$7+$B$9+16500*$B$10<=$B$8,"✓ AU","US/EU")
A41: Bahamas | B41: CARICOM | C41: 60 | D41: 5.8 | E41: 0.35 | F41: 0.98 | G41: =60*1000*8760*$B$6/$B$5/1000 | H41: 15800 | I41: =$B$7+$B$9+15800*$B$10 | J41: =IF($B$7+$B$9+15800*$B$10<=$B$8,"✓ AU","US/EU")
A42: Belize | B42: CARICOM | C42: 55 | D42: 5.5 | E42: 0.28 | F42: 0.55 | G42: =55*1000*8760*$B$6/$B$5/1000 | H42: 16200 | I42: =$B$7+$B$9+16200*$B$10 | J42: =IF($B$7+$B$9+16200*$B$10<=$B$8,"✓ AU","US/EU")
A43: St Lucia | B43: CARICOM | C43: 25 | D43: 5.6 | E43: 0.3 | F43: 0.95 | G43: =25*1000*8760*$B$6/$B$5/1000 | H43: 17100 | I43: =$B$7+$B$9+17100*$B$10 | J43: =IF($B$7+$B$9+17100*$B$10<=$B$8,"✓ AU","US/EU")
...

Sheet H2 Economics (AU)
A1: GREEN HYDROGEN → AUSTRALIAN GREEN IRON | ECONOMICS & MULTIPLIERS
A2: Phase 1: SRD funds energy sovereignty. Phase 2 (post-2031): Excess RE → H₂ export → AU green iron → Asian steel. ⚠ Green iron H₂ DRI is unproven at commercial scale. Model as contingent on AU industry scaling.
A4: PHASE 2 — H₂ IMPORT PARAMETERS (from document sources)
A5: Green Iron Target — single plant (Mtpa) | B5: 4.8 | C5: Source: Minerals Institute WA (single 4.8 Mtpa plant)
A6: H₂ intensity (kg H₂ per tonne DRI) | B6: 55 | C6: Source: Industry average; range 50–60 kg/t (technical literature)
A7: Total H₂ required — single plant (t/yr) | B7: =B5*B6*1000 | C7: green iron target × H₂ intensity × 1000 kg/t
A8: SIDS market share of AU H₂ demand | B8: 0.2 | C8: Assumption: 20% conservative. See sensitivity in row 15.
A9: SIDS H₂ export to AU — single plant (t/yr) | B9: =B7*B8 | C9: SIDS supply if 20% of single plant H₂ demand
A10: H₂ gate price ($/kg) | B10: 3.5 | C10: Source: CSIRO/ARENA 2025-2030 target; see Hydrogen Alliance sheet
A11: Annual H₂ export revenue — SIDS ($) | B11: =B9*1000*B10 | C11: t/yr × 1000 kg/t × $/kg
A13: SIDS MARKET SHARE SENSITIVITY (% of single plant H₂ demand)
A14: SIDS Market Share | B14: H₂ Export (t/yr) | C14: Annual Revenue ($)
A15: 0.05 | B15: =B7*0.05 | C15: =B7*0.05*1000*B10
A16: 0.1 | B16: =B7*0.1 | C16: =B7*0.1*1000*B10
A17: 0.15 | B17: =B7*0.15 | C17: =B7*0.15*1000*B10
A18: 0.2 | B18: =B7*0.2 | C18: =B7*0.2*1000*B10
A19: 0.3 | B19: =B7*0.3 | C19: =B7*0.3*1000*B10
A20: 0.4 | B20: =B7*0.4 | C20: =B7*0.4*1000*B10
A21: 0.5 | B21: =B7*0.5 | C21: =B7*0.5*1000*B10
A22: Highlighted row = base case (20%). Source: Assumption pending offtake agreements.
A24: SIDS SWF RECIPROCAL INVESTMENT IN AU GREEN IRON
A25: SIDS SWF Year 25 (from SWF Projection sheet) | B25: ='SWF Projection'!C28 | C25: Links to SWF Projection sheet C28
A26: Reciprocal investment rate | B26: 0.075 | C26: 7.5% of SWF to Australian assets (SRD doc)
A27: Total reciprocal investment ($) | B27: =B25*B26 | C27: SWF × 7.5%
A28: Allocation to green iron processing | B28: 0.6 | C28: 60% of reciprocal to green iron
A29: Investment in processing capacity ($) | B29: =B27*B28 | C29: reciprocal × 60%
A30: Estimated plant capex ($) | B30: 5000000000 | C30: Rough estimate; range $3–8B. Pending confirmed DRI projects.
A31: Equity stake in 4.8Mtpa plant | B31: =B29/B30 | C31: ≈ Processing investment ÷ plant capex
A32: Indirect jobs (proportional to stake) | B32: =1540*B31 | C32: Source: Minerals Institute WA (1,540 FTE per plant × equity %)
A33: ⚠ Plant capex ($5B) is a rough estimate. Real DRI plants vary $3–8B depending on scale, technology (shaft furnace vs flash calciner), and location. Update when DRI projects confirmed.
A35: ECONOMIC MULTIPLIERS — PER 4.8 Mtpa GREEN IRON PLANT
A36: Metric | B36: Value | C36: Source
A37: GDP contribution (cumulative) | B37: $85B | C37: Minerals Institute of WA (2024)
A38: Annual real income added | B38: $2.4B/yr | C38: Minerals Institute of WA (2024)
A39: Full-time jobs created | B39: 1,540 FTE | C39: Minerals Institute of WA (2024)
A40: Green iron export revenue | B40: $12–15B/yr | C40: Accenture / estimated
A41: State tax revenue (annual) | B41: ~$1.2B | C41: Estimated
A42: Industry export total by 2040 | B42: $122B | C42: Accenture Report (green metals industry)
A43: Annual range — full industry | B43: $96–295B/yr | C43: Deloitte / WWF-Australia Report
A44: AU Government Green Iron Fund | B44: $1B committed | C44: Dept of Industry, Science & Resources
...

Sheet Data Gaps Tracker
A1: DATA GAPS TRACKER — HYDROGEN ALLIANCE MODULE
A2: Track open data gaps. When a source becomes available, update Hydrogen Alliance and H2 Economics sheets. Priority = critical for model defensibility.
A4: OPEN DATA GAPS
A5: Data Gap | B5: Priority | C5: Source / Contact | D5: Expected Date | E5: Repo Path
A6: Pacific H₂ Strategy Report C (per-country resource maps, land availability, production cost estimates) | B6: CRITICAL | C6: DCCEEW/UNSW Sydney – Pacific H₂ Strategy | D6: Late 2026 | E6: data/raw/pacific_hydrogen_strategy/report_c/
A7: CCREEE Integrated Resource Plans — all 25 CARICOM nations (25-yr power sector plans) | B7: CRITICAL | C7: CCREEE – Dr Devon Gardner (Head of Technical Programs) | D7: End 2024 (8 done; 25 planned) | E7: data/raw/caricom_ccreee/integrated_resource_plans/
A8: Australian green iron H₂ demand trajectory (confirmed DRI plant pipeline) | B8: HIGH | C8: ARENA; Dept Industry Science & Resources; state govts (WA, SA, Qld) | D8: When announced | E8: data/raw/australia_green_iron/demand_trajectory/
A9: Calix ZESTY full techno-economic data (post-demonstration) | B9: HIGH | C9: ARENA (calix_zesty grant) | D9: Post-demo (~2027) | E9: data/raw/australia_green_iron/arena_calix_zesty/
A10: H₂ offtake agreements SIDS → Australia (when signed) | B10: HIGH | C10: ARENA / DISR | D10: TBD | E10: data/raw/offtake_agreements/
A11: Trinidad CertHiLAC certification data (clean H₂ certification system) | B11: MEDIUM | C11: IDB; OLADE (Latin America Energy Org) | D11: Available now | E11: data/raw/caricom_ccreee/trinidad_certhilac/
A12: Barbados HDF Energy/Rubis Renewstable project data (50MW solar+H₂, 2027) | B12: MEDIUM | C12: HDF Energy; Rubis Caribbean | D12: 2027 operational | E12: data/raw/caricom_ccreee/barbados_hydrogen_project/
A13: Per-country port depth, handling capacity, grid connection data | B13: MEDIUM | C13: National port authorities; national utilities | D13: On request | E13: data/raw/pacific_hydrogen_strategy/logistics/
A14: Green Iron Investment Fund project pipeline ($1B fund — project selection) | B14: LOW | C14: Dept Industry Science & Resources | D14: Rolling announcements | E14: data/raw/australia_green_iron/green_iron_fund/
A15: Open-source Pacific H₂ techno-economic assessment tool (DCCEEW in development) | B15: LOW | C15: DCCEEW; UNSW Sydney | D15: ~2026 | E15: data/raw/pacific_hydrogen_strategy/technoeconomic_tool/
